Workbook

Sheet Dashboard
A1: TRAINING DASHBOARD
A3: YOUR PROGRESSION BEST FRIEND
J4: 2026
J6: Barbell squat
G8: Number of sessions | J8: Total training time | M8: AVG training time
G9: =COUNTIF(Sessions[Year],J4) -> 5 | J9: =SUMIF(Sessions[Year],Dashboard!J4,Sessions[Training_Time]) -> 0.27430556 | M9: =IFERROR(AVERAGEIF(Sessions[Year],J4,Sessions[Training_Time]),0) -> 0.054861111
H12: Sum of series | I12: Sum of reps | K12: Max reps | L12: Max weight
H13: =COUNTIFS(Performance[Exercise_Name],Dashboard!$J$6,Performance[Year],Dashboard!$J$4) -> 16 | I13: =SUMIFS(Performance[Reps],Performance[Exercise_Name],Dashboard!J6,Performance[Year],$J$4) -> 187 | K13: =_xlfn.MAXIFS(Performance[Reps],Performance[Exercise_Name],Dashboard!$J$6,Performance[Year],$J$4) -> 19 | L13: =_xlfn.MAXIFS(Performance[Weight],Performance[Exercise_Name],Dashboard!$J$6,Performance[Year],$J$4) -> 100
J17: Last body measurments
F18: Weight | G18: Neck | H18: Chest | I18: Biceps | J18: Waits | K18: Stomach | L18: Hips | M18: Thigh | N18: Calf
F19: =IFERROR(INDEX(Weight!B:B,MATCH(999999999999999,Weight!B:B)),0) -> 83 | G19: =IFERROR(INDEX(Body_measurements!B:B,MATCH(9.99999999999999E+25,Body_measurements!B:B)),0) -> 29 | H19: =IFERROR(INDEX(Body_measurements!C:C,MATCH(9.99999999999999E+25,Body_measurements!C:C)),0) -> 81 | I19: =IFERROR(INDEX(Body_measurements!D:D,MATCH(9.99999999999999E+25,Body_measurements!D:D)),0) -> 31 | J19: =IFERROR(INDEX(Body_measurements!E:E,MATCH(9.99999999999999E+25,Body_measurements!E:E)),0) -> 71 | K19: =IFERROR(INDEX(Body_measurements!F:F,MATCH(9.99999999999999E+25,Body_measurements!F:F)),0) -> 71 | L19: =IFERROR(INDEX(Body_measurements!G:G,MATCH(9.99999999999999E+25,Body_measurements!G:G)),0) -> 71 | M19: =IFERROR(INDEX(Body_measurements!H:H,MATCH(9.99999999999999E+25,Body_measurements!H:H)),0) -> 42 | N19: =IFERROR(INDEX(Body_measurements!I:I,MATCH(9.99999999999999E+25,Body_measurements!I:I)),0) -> 31
D46: January | E46: February | F46: March | G46: April | H46: May | I46: June | J46: July | K46: August | L46: September | M46: October | N46: November | O46: December
C47: Avg series | D47: =COUNTIFS(Performance[[Exercise_Name]:[Exercise_Name]],Dashboard!$J$6,Performance[[Year]:[Year]],Dashboard!$J$4,Performance[[Month]:[Month]],D$46) -> 0 | E47: =COUNTIFS(Performance[[Exercise_Name]:[Exercise_Name]],Dashboard!$J$6,Performance[[Year]:[Year]],Dashboard!$J$4,Performance[[Month]:[Month]],E$46) -> 4 | F47: =COUNTIFS(Performance[[Exercise_Name]:[Exercise_Name]],Dashboard!$J$6,Performance[[Year]:[Year]],Dashboard!$J$4,Performance[[Month]:[Month]],F$46) -> 4 | G47: =COUNTIFS(Performance[[Exercise_Name]:[Exercise_Name]],Dashboard!$J$6,Performance[[Year]:[Year]],Dashboard!$J$4,Performance[[Month]:[Month]],G$46) -> 4 | H47: =COUNTIFS(Performance[[Exercise_Name]:[Exercise_Name]],Dashboard!$J$6,Performance[[Year]:[Year]],Dashboard!$J$4,Performance[[Month]:[Month]],H$46) -> 4 | I47: =COUNTIFS(Performance[[Exercise_Name]:[Exercise_Name]],Dashboard!$J$6,Performance[[Year]:[Year]],Dashboard!$J$4,Performance[[Month]:[Month]],I$46) -> 0 | J47: =COUNTIFS(Performance[[Exercise_Name]:[Exercise_Name]],Dashboard!$J$6,Performance[[Year]:[Year]],Dashboard!$J$4,Performance[[Month]:[Month]],J$46) -> 0 | K47: =COUNTIFS(Performance[[Exercise_Name]:[Exercise_Name]],Dashboard!$J$6,Performance[[Year]:[Year]],Dashboard!$J$4,Performance[[Month]:[Month]],K$46) -> 0 | ... O47: =COUNTIFS(Performance[[Exercise_Name]:[Exercise_Name]],Dashboard!$J$6,Performance[[Year]:[Year]],Dashboard!$J$4,Performance[[Month]:[Month]],O$46) -> 0
C48: Avg reps | D48: =IFERROR(AVERAGEIFS(Performance[[Reps]:[Reps]],Performance[[Exercise_Name]:[Exercise_Name]],$J$6,Performance[[Year]:[Year]],$J$4,Performance[[Month]:[Month]],D$46),0) -> 0 | E48: =IFERROR(AVERAGEIFS(Performance[[Reps]:[Reps]],Performance[[Exercise_Name]:[Exercise_Name]],$J$6,Performance[[Year]:[Year]],$J$4,Performance[[Month]:[Month]],E$46),0) -> 6.5 | F48: =IFERROR(AVERAGEIFS(Performance[[Reps]:[Reps]],Performance[[Exercise_Name]:[Exercise_Name]],$J$6,Performance[[Year]:[Year]],$J$4,Performance[[Month]:[Month]],F$46),0) -> 15.5 | G48: =IFERROR(AVERAGEIFS(Performance[[Reps]:[Reps]],Performance[[Exercise_Name]:[Exercise_Name]],$J$6,Performance[[Year]:[Year]],$J$4,Performance[[Month]:[Month]],G$46),0) -> 12.25 | H48: =IFERROR(AVERAGEIFS(Performance[[Reps]:[Reps]],Performance[[Exercise_Name]:[Exercise_Name]],$J$6,Performance[[Year]:[Year]],$J$4,Performance[[Month]:[Month]],H$46),0) -> 12.5 | I48: =IFERROR(AVERAGEIFS(Performance[[Reps]:[Reps]],Performance[[Exercise_Name]:[Exercise_Name]],$J$6,Performance[[Year]:[Year]],$J$4,Performance[[Month]:[Month]],I$46),0) -> 0 | J48: =IFERROR(AVERAGEIFS(Performance[[Reps]:[Reps]],Performance[[Exercise_Name]:[Exercise_Name]],$J$6,Performance[[Year]:[Year]],$J$4,Performance[[Month]:[Month]],J$46),0) -> 0 | K48: =IFERROR(AVERAGEIFS(Performance[[Reps]:[Reps]],Performance[[Exercise_Name]:[Exercise_Name]],$J$6,Performance[[Year]:[Year]],$J$4,Performance[[Month]:[Month]],K$46),0) -> 0 | ... O48: =IFERROR(AVERAGEIFS(Performance[[Reps]:[Reps]],Performance[[Exercise_Name]:[Exercise_Name]],$J$6,Performance[[Year]:[Year]],$J$4,Performance[[Month]:[Month]],O$46),0) -> 0
C49: Avg weight | D49: =IFERROR(AVERAGEIFS(Performance[[Weight]:[Weight]],Performance[[Exercise_Name]:[Exercise_Name]],$J$6,Performance[[Year]:[Year]],$J$4,Performance[[Month]:[Month]],D$46),0) -> 0 | E49: =IFERROR(AVERAGEIFS(Performance[[Weight]:[Weight]],Performance[[Exercise_Name]:[Exercise_Name]],$J$6,Performance[[Year]:[Year]],$J$4,Performance[[Month]:[Month]],E$46),0) -> 65 | F49: =IFERROR(AVERAGEIFS(Performance[[Weight]:[Weight]],Performance[[Exercise_Name]:[Exercise_Name]],$J$6,Performance[[Year]:[Year]],$J$4,Performance[[Month]:[Month]],F$46),0) -> 49.5 | G49: =IFERROR(AVERAGEIFS(Performance[[Weight]:[Weight]],Performance[[Exercise_Name]:[Exercise_Name]],$J$6,Performance[[Year]:[Year]],$J$4,Performance[[Month]:[Month]],G$46),0) -> 68 | H49: =IFERROR(AVERAGEIFS(Performance[[Weight]:[Weight]],Performance[[Exercise_Name]:[Exercise_Name]],$J$6,Performance[[Year]:[Year]],$J$4,Performance[[Month]:[Month]],H$46),0) -> 40.25 | I49: =IFERROR(AVERAGEIFS(Performance[[Weight]:[Weight]],Performance[[Exercise_Name]:[Exercise_Name]],$J$6,Performance[[Year]:[Year]],$J$4,Performance[[Month]:[Month]],I$46),0) -> 0 | J49: =IFERROR(AVERAGEIFS(Performance[[Weight]:[Weight]],Performance[[Exercise_Name]:[Exercise_Name]],$J$6,Performance[[Year]:[Year]],$J$4,Performance[[Month]:[Month]],J$46),0) -> 0 | K49: =IFERROR(AVERAGEIFS(Performance[[Weight]:[Weight]],Performance[[Exercise_Name]:[Exercise_Name]],$J$6,Performance[[Year]:[Year]],$J$4,Performance[[Month]:[Month]],K$46),0) -> 0 | ... O49: =IFERROR(AVERAGEIFS(Performance[[Weight]:[Weight]],Performance[[Exercise_Name]:[Exercise_Name]],$J$6,Performance[[Year]:[Year]],$J$4,Performance[[Month]:[Month]],O$46),0) -> 0
C50: Avg volume | D50: =IFERROR(AVERAGEIFS(Performance[[Volume]:[Volume]],Performance[[Exercise_Name]:[Exercise_Name]],$J$6,Performance[[Year]:[Year]],$J$4,Performance[[Month]:[Month]],D$46),0) -> 0 | E50: =IFERROR(AVERAGEIFS(Performance[[Volume]:[Volume]],Performance[[Exercise_Name]:[Exercise_Name]],$J$6,Performance[[Year]:[Year]],$J$4,Performance[[Month]:[Month]],E$46),0) -> 405 | F50: =IFERROR(AVERAGEIFS(Performance[[Volume]:[Volume]],Performance[[Exercise_Name]:[Exercise_Name]],$J$6,Performance[[Year]:[Year]],$J$4,Performance[[Month]:[Month]],F$46),0) -> 800 | G50: =IFERROR(AVERAGEIFS(Performance[[Volume]:[Volume]],Performance[[Exercise_Name]:[Exercise_Name]],$J$6,Performance[[Year]:[Year]],$J$4,Performance[[Month]:[Month]],G$46),0) -> 900.25 | H50: =IFERROR(AVERAGEIFS(Performance[[Volume]:[Volume]],Performance[[Exercise_Name]:[Exercise_Name]],$J$6,Performance[[Year]:[Year]],$J$4,Performance[[Month]:[Month]],H$46),0) -> 612.5 | I50: =IFERROR(AVERAGEIFS(Performance[[Volume]:[Volume]],Performance[[Exercise_Name]:[Exercise_Name]],$J$6,Performance[[Year]:[Year]],$J$4,Performance[[Month]:[Month]],I$46),0) -> 0 | J50: =IFERROR(AVERAGEIFS(Performance[[Volume]:[Volume]],Performance[[Exercise_Name]:[Exercise_Name]],$J$6,Performance[[Year]:[Year]],$J$4,Performance[[Month]:[Month]],J$46),0) -> 0 | K50: =IFERROR(AVERAGEIFS(Performance[[Volume]:[Volume]],Performance[[Exercise_Name]:[Exercise_Name]],$J$6,Performance[[Year]:[Year]],$J$4,Performance[[Month]:[Month]],K$46),0) -> 0 | ... O50: =IFERROR(AVERAGEIFS(Performance[[Volume]:[Volume]],Performance[[Exercise_Name]:[Exercise_Name]],$J$6,Performance[[Year]:[Year]],$J$4,Performance[[Month]:[Month]],O$46),0) -> 0

Sheet Sessions
A1: Session_ID | B1: Date | C1: Training_Name | D1: Start_Time | E1: End_Time | F1: Energy_Level | G1: Training_Time | H1: Session_Volume | I1: Year | J1: Month | K1: Day_of_week
A2: {=ROW()-ROW(Sessions[#Headers])} -> 1 | B2: 46056 | C2: A | D2: 0.52083333 | E2: 0.63888889 | F2: 5 | G2: =Sessions[[#This Row],[End_Time]]-Sessions[[#This Row],[Start_Time]] -> 0.11805556 | H2: =SUMIF(Performance[Session_ID],Sessions[[#This Row],[Session_ID]],Performance[Volume]) -> 13116 | I2: =YEAR(Sessions[[#This Row],[Date]]) -> 2026 | J2: =_xlfn.XLOOKUP(MONTH(Sessions[[#This Row],[Date]]),Mapping!$K$1:$K$12,Mapping!$L$1:$L$12) -> February | K2: =_xlfn.XLOOKUP(WEEKDAY(Sessions[[#This Row],[Date]]),Mapping!$N$1:$N$7,Mapping!$O$1:$O$7,) -> Wednesday
A3: {=ROW()-ROW(Sessions[#Headers])} -> 2 | B3: 46085 | C3: B | D3: 0.5 | E3: 0.5625 | F3: 3 | G3: =Sessions[[#This Row],[End_Time]]-Sessions[[#This Row],[Start_Time]] -> 0.0625 | H3: =SUMIF(Performance[Session_ID],Sessions[[#This Row],[Session_ID]],Performance[Volume]) -> 18484 | I3: =YEAR(Sessions[[#This Row],[Date]]) -> 2026 | J3: =_xlfn.XLOOKUP(MONTH(Sessions[[#This Row],[Date]]),Mapping!$K$1:$K$12,Mapping!$L$1:$L$12) -> March | K3: =_xlfn.XLOOKUP(WEEKDAY(Sessions[[#This Row],[Date]]),Mapping!$N$1:$N$7,Mapping!$O$1:$O$7,) -> Thursday
A4: {=ROW()-ROW(Sessions[#Headers])} -> 3 | B4: 46117 | C4: C | D4: 0.70833333 | E4: 0.80208333 | F4: 1 | G4: =Sessions[[#This Row],[End_Time]]-Sessions[[#This Row],[Start_Time]] -> 0.09375 | H4: =SUMIF(Performance[Session_ID],Sessions[[#This Row],[Session_ID]],Performance[Volume]) -> 12410 | I4: =YEAR(Sessions[[#This Row],[Date]]) -> 2026 | J4: =_xlfn.XLOOKUP(MONTH(Sessions[[#This Row],[Date]]),Mapping!$K$1:$K$12,Mapping!$L$1:$L$12) -> April | K4: =_xlfn.XLOOKUP(WEEKDAY(Sessions[[#This Row],[Date]]),Mapping!$N$1:$N$7,Mapping!$O$1:$O$7,) -> Monday
A5: {=ROW()-ROW(Sessions[#Headers])} -> 4 | B5: 46148 | G5: =Sessions[[#This Row],[End_Time]]-Sessions[[#This Row],[Start_Time]] -> 0 | H5: =SUMIF(Performance[Session_ID],Sessions[[#This Row],[Session_ID]],Performance[Volume]) -> 13389 | I5: =YEAR(Sessions[[#This Row],[Date]]) -> 2026 | J5: =_xlfn.XLOOKUP(MONTH(Sessions[[#This Row],[Date]]),Mapping!$K$1:$K$12,Mapping!$L$1:$L$12) -> May | K5: =_xlfn.XLOOKUP(WEEKDAY(Sessions[[#This Row],[Date]]),Mapping!$N$1:$N$7,Mapping!$O$1:$O$7,) -> Thursday
A6: {=ROW()-ROW(Sessions[#Headers])} -> 5 | B6: 46180 | G6: =Sessions[[#This Row],[End_Time]]-Sessions[[#This Row],[Start_Time]] -> 0 | H6: =SUMIF(Performance[Session_ID],Sessions[[#This Row],[Session_ID]],Performance[Volume]) -> 0 | I6: =YEAR(Sessions[[#This Row],[Date]]) -> 2026 | J6: =_xlfn.XLOOKUP(MONTH(Sessions[[#This Row],[Date]]),Mapping!$K$1:$K$12,Mapping!$L$1:$L$12) -> June | K6: =_xlfn.XLOOKUP(WEEKDAY(Sessions[[#This Row],[Date]]),Mapping!$N$1:$N$7,Mapping!$O$1:$O$7,) -> Monday

Sheet Exercises
A1: Exercise_ID | B1: Exercise_Name | C1: Muscle_Group | D1: Equipment
A2: {="EX-" & TEXT(ROW()-ROW(Exercises[#Headers]),"000")} -> EX-001 | B2: Russian twist | C2: Abdominals | D2: Bodyweight
A3: {="EX-" & TEXT(ROW()-ROW(Exercises[#Headers]),"000")} -> EX-002 | B3: Plank | C3: Abdominals | D3: Bodyweight
A4: {="EX-" & TEXT(ROW()-ROW(Exercises[#Headers]),"000")} -> EX-003 | B4: Hollow body | C4: Abdominals | D4: Bodyweight
A5: {="EX-" & TEXT(ROW()-ROW(Exercises[#Headers]),"000")} -> EX-004 | B5: Leg raises | C5: Abdominals | D5: Bodyweight
A6: {="EX-" & TEXT(ROW()-ROW(Exercises[#Headers]),"000")} -> EX-005 | B6: Machine core | C6: Abdominals | D6: Machine
A7: {="EX-" & TEXT(ROW()-ROW(Exercises[#Headers]),"000")} -> EX-006 | B7: Reverse plank | C7: Abdominals | D7: Bodyweight
A8: {="EX-" & TEXT(ROW()-ROW(Exercises[#Headers]),"000")} -> EX-007 | B8: Crunches | C8: Abdominals | D8: Bodyweight
A9: {="EX-" & TEXT(ROW()-ROW(Exercises[#Headers]),"000")} -> EX-008 | B9: Leg raises: hanging | C9: Abdominals
A10: {="EX-" & TEXT(ROW()-ROW(Exercises[#Headers]),"000")} -> EX-009 | B10: Wheel | C10: Abdominals
A11: {="EX-" & TEXT(ROW()-ROW(Exercises[#Headers]),"000")} -> EX-010 | B11: Ball plank | C11: Abdominals
A12: {="EX-" & TEXT(ROW()-ROW(Exercises[#Headers]),"000")} -> EX-011 | B12: Roman bench Bend | C12: Abdominals
A13: {="EX-" & TEXT(ROW()-ROW(Exercises[#Headers]),"000")} -> EX-012 | B13: Crunches: bench | C13: Abdominals
A14: {="EX-" & TEXT(ROW()-ROW(Exercises[#Headers]),"000")} -> EX-013 | B14: Cable crunch | C14: Abdominals
A15: {="EX-" & TEXT(ROW()-ROW(Exercises[#Headers]),"000")} -> EX-014 | B15: Mountain Climbers | C15: Abdominals
A16: {="EX-" & TEXT(ROW()-ROW(Exercises[#Headers]),"000")} -> EX-015 | B16: Barbell swing | C16: Abdominals
A17: {="EX-" & TEXT(ROW()-ROW(Exercises[#Headers]),"000")} -> EX-016 | B17: Woodchoppers | C17: Abdominals
A18: {="EX-" & TEXT(ROW()-ROW(Exercises[#Headers]),"000")} -> EX-017 | B18: Side plank | C18: Abdominals
A19: {="EX-" & TEXT(ROW()-ROW(Exercises[#Headers]),"000")} -> EX-018 | B19: Crunches (reps/time in s) | C19: Abdominals
A20: {="EX-" & TEXT(ROW()-ROW(Exercises[#Headers]),"000")} -> EX-019 | B20: Pull ups | C20: Back muscles
... A85: {="EX-" & TEXT(ROW()-ROW(Exercises[#Headers]),"000")} -> EX-084 | B85: Shrugs | C85: Traps
A86: {="EX-" & TEXT(ROW()-ROW(Exercises[#Headers]),"000")} -> EX-085 | B86: Dips | C86: Triceps | D86: Bodyweight
A87: {="EX-" & TEXT(ROW()-ROW(Exercises[#Headers]),"000")} -> EX-086 | B87: Triceps cables: long head | C87: Triceps
A88: {="EX-" & TEXT(ROW()-ROW(Exercises[#Headers]),"000")} -> EX-087 | B88: Triceps cables: push down | C88: Triceps
A89: {="EX-" & TEXT(ROW()-ROW(Exercises[#Headers]),"000")} -> EX-088 | B89: Triceps dumbbbell: behind head | C89: Triceps
A90: {="EX-" & TEXT(ROW()-ROW(Exercises[#Headers]),"000")} -> EX-089 | B90: Triceps bench: dumbbell | C90: Triceps
A91: {="EX-" & TEXT(ROW()-ROW(Exercises[#Headers]),"000")} -> EX-090 | B91: Lying French Press | C91: Triceps
A92: {="EX-" & TEXT(ROW()-ROW(Exercises[#Headers]),"000")} -> EX-091 | B92: Close grip bench press | C92: Triceps
A93: {="EX-" & TEXT(ROW()-ROW(Exercises[#Headers]),"000")} -> EX-092 | B93: Dips - machine | C93: Triceps | D93: Machine
A94: {="EX-" & TEXT(ROW()-ROW(Exercises[#Headers]),"000")} -> EX-093 | B94: Deadlift straight legs | C94: Two-headed
A95: {="EX-" & TEXT(ROW()-ROW(Exercises[#Headers]),"000")} -> EX-094 | B95: Facepull TRX | C95: Upper body
A96: {="EX-" & TEXT(ROW()-ROW(Exercises[#Headers]),"000")} -> EX-095 | B96: Wrist circulation band | C96: Wrist
A97: {="EX-" & TEXT(ROW()-ROW(Exercises[#Headers]),"000")} -> EX-096 | B97: Wrist curls band | C97: Wrist
A98: {="EX-" & TEXT(ROW()-ROW(Exercises[#Headers]),"000")} -> EX-097 | B98: Wrist curls | C98: Wrist
A99: {="EX-" & TEXT(ROW()-ROW(Exercises[#Headers]),"000")} -> EX-098 | B99: Wrist rotations | C99: Wrist
A100: {="EX-" & TEXT(ROW()-ROW(Exercises[#Headers]),"000")} -> EX-099 | B100: Wall wrist stretch | C100: Wrist
A101: {="EX-" & TEXT(ROW()-ROW(Exercises[#Headers]),"000")} -> EX-100 | B101: Grip squeezer | C101: Wrist
A102: {="EX-" & TEXT(ROW()-ROW(Exercises[#Headers]),"000")} -> EX-101 | B102: Nordics | C102: Legs
A103: {="EX-" & TEXT(ROW()-ROW(Exercises[#Headers]),"000")} -> EX-102 | B103: Machine Reverse Fly | C103: Shoulders
A104: {="EX-" & TEXT(ROW()-ROW(Exercises[#Headers]),"000")} -> EX-103 | B104: Allah curls | C104: Abdominals
...

Sheet Performance
A1: Session_ID | B1: Date | C1: Exercise_Name | D1: Set_Number | E1: Reps | F1: Weight | G1: RIR | H1: RPE | I1: RPE_Detalis | J1: Volume | K1: Exercise_ID | L1: Year | M1: Month | N1: Day
A2: 1 | B2: =_xlfn.XLOOKUP(Performance[[#This Row],[Session_ID]],Sessions[Session_ID],Sessions[Date],"Not found") -> 46056 | C2: Hip bridge from the ground | D2: 1 | E2: 8 | F2: 90 | G2: 3 | H2: =IF(Performance[[#This Row],[RIR]]="","",10-Performance[[#This Row],[RIR]]) -> 7 | I2: {=_xlfn.XLOOKUP(Performance[[#This Row],[RPE]],RPE_Detalis[[#All],[RPE]],RPE_Detalis[[#All],[Detalis]],"")} -> Hard, but controlled | J2: =Performance[[#This Row],[Reps]]*Performance[[#This Row],[Weight]] -> 720 | K2: =_xlfn.XLOOKUP(Performance[[#This Row],[Exercise_Name]],Exercises[Exercise_Name],Exercises[Exercise_ID],"Not found") -> EX-113 | L2: =YEAR(Performance[[#This Row],[Date]]) -> 2026 | M2: =_xlfn.XLOOKUP(MONTH(Performance[[#This Row],[Date]]),Mapping!$K$1:$K$12,Mapping!$L$1:$L$12) -> February | N2: =_xlfn.XLOOKUP(WEEKDAY(Performance[[#This Row],[Date]]),Mapping!$N$1:$N$7,Mapping!$O$1:$O$7,) -> Wednesday
A3: 1 | B3: =_xlfn.XLOOKUP(Performance[[#This Row],[Session_ID]],Sessions[Session_ID],Sessions[Date],"Not found") -> 46056 | C3: Hip bridge from the ground | D3: 2 | E3: 8 | F3: 90 | G3: 3 | H3: =IF(Performance[[#This Row],[RIR]]="","",10-Performance[[#This Row],[RIR]]) -> 7 | I3: {=_xlfn.XLOOKUP(Performance[[#This Row],[RPE]],RPE_Detalis[[#All],[RPE]],RPE_Detalis[[#All],[Detalis]],"")} -> Hard, but controlled | J3: =Performance[[#This Row],[Reps]]*Performance[[#This Row],[Weight]] -> 720 | K3: =_xlfn.XLOOKUP(Performance[[#This Row],[Exercise_Name]],Exercises[Exercise_Name],Exercises[Exercise_ID],"Not found") -> EX-113 | L3: =YEAR(Performance[[#This Row],[Date]]) -> 2026 | M3: =_xlfn.XLOOKUP(MONTH(Performance[[#This Row],[Date]]),Mapping!$K$1:$K$12,Mapping!$L$1:$L$12) -> February | N3: =_xlfn.XLOOKUP(WEEKDAY(Performance[[#This Row],[Date]]),Mapping!$N$1:$N$7,Mapping!$O$1:$O$7,) -> Wednesday
A4: 1 | B4: =_xlfn.XLOOKUP(Performance[[#This Row],[Session_ID]],Sessions[Session_ID],Sessions[Date],"Not found") -> 46056 | C4: Hip bridge from the ground | D4: 3 | E4: 8 | F4: 110 | G4: 3 | H4: =IF(Performance[[#This Row],[RIR]]="","",10-Performance[[#This Row],[RIR]]) -> 7 | I4: {=_xlfn.XLOOKUP(Performance[[#This Row],[RPE]],RPE_Detalis[[#All],[RPE]],RPE_Detalis[[#All],[Detalis]],"")} -> Hard, but controlled | J4: =Performance[[#This Row],[Reps]]*Performance[[#This Row],[Weight]] -> 880 | K4: =_xlfn.XLOOKUP(Performance[[#This Row],[Exercise_Name]],Exercises[Exercise_Name],Exercises[Exercise_ID],"Not found") -> EX-113 | L4: =YEAR(Performance[[#This Row],[Date]]) -> 2026 | M4: =_xlfn.XLOOKUP(MONTH(Performance[[#This Row],[Date]]),Mapping!$K$1:$K$12,Mapping!$L$1:$L$12) -> February | N4: =_xlfn.XLOOKUP(WEEKDAY(Performance[[#This Row],[Date]]),Mapping!$N$1:$N$7,Mapping!$O$1:$O$7,) -> Wednesday
A5: 1 | B5: =_xlfn.XLOOKUP(Performance[[#This Row],[Session_ID]],Sessions[Session_ID],Sessions[Date],"Not found") -> 46056 | C5: Hip bridge from the ground | D5: 4 | E5: 8 | F5: 110 | G5: 3 | H5: =IF(Performance[[#This Row],[RIR]]="","",10-Performance[[#This Row],[RIR]]) -> 7 | I5: {=_xlfn.XLOOKUP(Performance[[#This Row],[RPE]],RPE_Detalis[[#All],[RPE]],RPE_Detalis[[#All],[Detalis]],"")} -> Hard, but controlled | J5: =Performance[[#This Row],[Reps]]*Performance[[#This Row],[Weight]] -> 880 | K5: =_xlfn.XLOOKUP(Performance[[#This Row],[Exercise_Name]],Exercises[Exercise_Name],Exercises[Exercise_ID],"Not found") -> EX-113 | L5: =YEAR(Performance[[#This Row],[Date]]) -> 2026 | M5: =_xlfn.XLOOKUP(MONTH(Performance[[#This Row],[Date]]),Mapping!$K$1:$K$12,Mapping!$L$1:$L$12) -> February | N5: =_xlfn.XLOOKUP(WEEKDAY(Performance[[#This Row],[Date]]),Mapping!$N$1:$N$7,Mapping!$O$1:$O$7,) -> Wednesday
A6: 1 | B6: =_xlfn.XLOOKUP(Performance[[#This Row],[Session_ID]],Sessions[Session_ID],Sessions[Date],"Not found") -> 46056 | C6: Barbell squat | D6: 1 | E6: 10 | F6: 50 | G6: 5 | H6: =IF(Performance[[#This Row],[RIR]]="","",10-Performance[[#This Row],[RIR]]) -> 5 | I6: {=_xlfn.XLOOKUP(Performance[[#This Row],[RPE]],RPE_Detalis[[#All],[RPE]],RPE_Detalis[[#All],[Detalis]],"")} -> Warm-up / technic | J6: =Performance[[#This Row],[Reps]]*Performance[[#This Row],[Weight]] -> 500 | K6: =_xlfn.XLOOKUP(Performance[[#This Row],[Exercise_Name]],Exercises[Exercise_Name],Exercises[Exercise_ID],"Not found") -> EX-061 | L6: =YEAR(Performance[[#This Row],[Date]]) -> 2026 | M6: =_xlfn.XLOOKUP(MONTH(Performance[[#This Row],[Date]]),Mapping!$K$1:$K$12,Mapping!$L$1:$L$12) -> February | N6: =_xlfn.XLOOKUP(WEEKDAY(Performance[[#This Row],[Date]]),Mapping!$N$1:$N$7,Mapping!$O$1:$O$7,) -> Wednesday
A7: 1 | B7: =_xlfn.XLOOKUP(Performance[[#This Row],[Session_ID]],Sessions[Session_ID],Sessions[Date],"Not found") -> 46056 | C7: Barbell squat | D7: 2 | E7: 6 | F7: 70 | G7: 2 | H7: =IF(Performance[[#This Row],[RIR]]="","",10-Performance[[#This Row],[RIR]]) -> 8 | I7: {=_xlfn.XLOOKUP(Performance[[#This Row],[RPE]],RPE_Detalis[[#All],[RPE]],RPE_Detalis[[#All],[Detalis]],"")} -> Hard | J7: =Performance[[#This Row],[Reps]]*Performance[[#This Row],[Weight]] -> 420 | K7: =_xlfn.XLOOKUP(Performance[[#This Row],[Exercise_Name]],Exercises[Exercise_Name],Exercises[Exercise_ID],"Not found") -> EX-061 | L7: =YEAR(Performance[[#This Row],[Date]]) -> 2026 | M7: =_xlfn.XLOOKUP(MONTH(Performance[[#This Row],[Date]]),Mapping!$K$1:$K$12,Mapping!$L$1:$L$12) -> February | N7: =_xlfn.XLOOKUP(WEEKDAY(Performance[[#This Row],[Date]]),Mapping!$N$1:$N$7,Mapping!$O$1:$O$7,) -> Wednesday
A8: 1 | B8: =_xlfn.XLOOKUP(Performance[[#This Row],[Session_ID]],Sessions[Session_ID],Sessions[Date],"Not found") -> 46056 | C8: Barbell squat | D8: 3 | E8: 5 | F8: 70 | G8: 2 | H8: =IF(Performance[[#This Row],[RIR]]="","",10-Performance[[#This Row],[RIR]]) -> 8 | I8: {=_xlfn.XLOOKUP(Performance[[#This Row],[RPE]],RPE_Detalis[[#All],[RPE]],RPE_Detalis[[#All],[Detalis]],"")} -> Hard | J8: =Performance[[#This Row],[Reps]]*Performance[[#This Row],[Weight]] -> 350 | K8: =_xlfn.XLOOKUP(Performance[[#This Row],[Exercise_Name]],Exercises[Exercise_Name],Exercises[Exercise_ID],"Not found") -> EX-061 | L8: =YEAR(Performance[[#This Row],[Date]]) -> 2026 | M8: =_xlfn.XLOOKUP(MONTH(Performance[[#This Row],[Date]]),Mapping!$K$1:$K$12,Mapping!$L$1:$L$12) -> February | N8: =_xlfn.XLOOKUP(WEEKDAY(Performance[[#This Row],[Date]]),Mapping!$N$1:$N$7,Mapping!$O$1:$O$7,) -> Wednesday
A9: 1 | B9: =_xlfn.XLOOKUP(Performance[[#This Row],[Session_ID]],Sessions[Session_ID],Sessions[Date],"Not found") -> 46056 | C9: Barbell squat | D9: 4 | E9: 5 | F9: 70 | G9: 2 | H9: =IF(Performance[[#This Row],[RIR]]="","",10-Performance[[#This Row],[RIR]]) -> 8 | I9: {=_xlfn.XLOOKUP(Performance[[#This Row],[RPE]],RPE_Detalis[[#All],[RPE]],RPE_Detalis[[#All],[Detalis]],"")} -> Hard | J9: =Performance[[#This Row],[Reps]]*Performance[[#This Row],[Weight]] -> 350 | K9: =_xlfn.XLOOKUP(Performance[[#This Row],[Exercise_Name]],Exercises[Exercise_Name],Exercises[Exercise_ID],"Not found") -> EX-061 | L9: =YEAR(Performance[[#This Row],[Date]]) -> 2026 | M9: =_xlfn.XLOOKUP(MONTH(Performance[[#This Row],[Date]]),Mapping!$K$1:$K$12,Mapping!$L$1:$L$12) -> February | N9: =_xlfn.XLOOKUP(WEEKDAY(Performance[[#This Row],[Date]]),Mapping!$N$1:$N$7,Mapping!$O$1:$O$7,) -> Wednesday
A10: 1 | B10: =_xlfn.XLOOKUP(Performance[[#This Row],[Session_ID]],Sessions[Session_ID],Sessions[Date],"Not found") -> 46056 | C10: RDL one leg | D10: 1 | E10: 20 | F10: 20 | G10: 3 | H10: =IF(Performance[[#This Row],[RIR]]="","",10-Performance[[#This Row],[RIR]]) -> 7 | I10: {=_xlfn.XLOOKUP(Performance[[#This Row],[RPE]],RPE_Detalis[[#All],[RPE]],RPE_Detalis[[#All],[Detalis]],"")} -> Hard, but controlled | J10: =Performance[[#This Row],[Reps]]*Performance[[#This Row],[Weight]] -> 400 | K10: =_xlfn.XLOOKUP(Performance[[#This Row],[Exercise_Name]],Exercises[Exercise_Name],Exercises[Exercise_ID],"Not found") -> EX-115 | L10: =YEAR(Performance[[#This Row],[Date]]) -> 2026 | M10: =_xlfn.XLOOKUP(MONTH(Performance[[#This Row],[Date]]),Mapping!$K$1:$K$12,Mapping!$L$1:$L$12) -> February | N10: =_xlfn.XLOOKUP(WEEKDAY(Performance[[#This Row],[Date]]),Mapping!$N$1:$N$7,Mapping!$O$1:$O$7,) -> Wednesday
A11: 1 | B11: =_xlfn.XLOOKUP(Performance[[#This Row],[Session_ID]],Sessions[Session_ID],Sessions[Date],"Not found") -> 46056 | C11: RDL one leg | D11: 2 | E11: 20 | F11: 20 | G11: 3 | H11: =IF(Performance[[#This Row],[RIR]]="","",10-Performance[[#This Row],[RIR]]) -> 7 | I11: {=_xlfn.XLOOKUP(Performance[[#This Row],[RPE]],RPE_Detalis[[#All],[RPE]],RPE_Detalis[[#All],[Detalis]],"")} -> Hard, but controlled | J11: =Performance[[#This Row],[Reps]]*Performance[[#This Row],[Weight]] -> 400 | K11: =_xlfn.XLOOKUP(Performance[[#This Row],[Exercise_Name]],Exercises[Exercise_Name],Exercises[Exercise_ID],"Not found") -> EX-115 | L11: =YEAR(Performance[[#This Row],[Date]]) -> 2026 | M11: =_xlfn.XLOOKUP(MONTH(Performance[[#This Row],[Date]]),Mapping!$K$1:$K$12,Mapping!$L$1:$L$12) -> February | N11: =_xlfn.XLOOKUP(WEEKDAY(Performance[[#This Row],[Date]]),Mapping!$N$1:$N$7,Mapping!$O$1:$O$7,) -> Wednesday
A12: 1 | B12: =_xlfn.XLOOKUP(Performance[[#This Row],[Session_ID]],Sessions[Session_ID],Sessions[Date],"Not found") -> 46056 | C12: RDL one leg | D12: 3 | E12: 20 | F12: 20 | G12: 2 | H12: =IF(Performance[[#This Row],[RIR]]="","",10-Performance[[#This Row],[RIR]]) -> 8 | I12: {=_xlfn.XLOOKUP(Performance[[#This Row],[RPE]],RPE_Detalis[[#All],[RPE]],RPE_Detalis[[#All],[Detalis]],"")} -> Hard | J12: =Performance[[#This Row],[Reps]]*Performance[[#This Row],[Weight]] -> 400 | K12: =_xlfn.XLOOKUP(Performance[[#This Row],[Exercise_Name]],Exercises[Exercise_Name],Exercises[Exercise_ID],"Not found") -> EX-115 | L12: =YEAR(Performance[[#This Row],[Date]]) -> 2026 | M12: =_xlfn.XLOOKUP(MONTH(Performance[[#This Row],[Date]]),Mapping!$K$1:$K$12,Mapping!$L$1:$L$12) -> February | N12: =_xlfn.XLOOKUP(WEEKDAY(Performance[[#This Row],[Date]]),Mapping!$N$1:$N$7,Mapping!$O$1:$O$7,) -> Wednesday
A13: 1 | B13: =_xlfn.XLOOKUP(Performance[[#This Row],[Session_ID]],Sessions[Session_ID],Sessions[Date],"Not found") -> 46056 | C13: Calf raises | D13: 1 | E13: 18 | F13: 140 | G13: 1 | H13: =IF(Performance[[#This Row],[RIR]]="","",10-Performance[[#This Row],[RIR]]) -> 9 | I13: {=_xlfn.XLOOKUP(Performance[[#This Row],[RPE]],RPE_Detalis[[#All],[RPE]],RPE_Detalis[[#All],[Detalis]],"")} -> Very hard, almost max | J13: =Performance[[#This Row],[Reps]]*Performance[[#This Row],[Weight]] -> 2520 | K13: =_xlfn.XLOOKUP(Performance[[#This Row],[Exercise_Name]],Exercises[Exercise_Name],Exercises[Exercise_ID],"Not found") -> EX-111 | L13: =YEAR(Performance[[#This Row],[Date]]) -> 2026 | M13: =_xlfn.XLOOKUP(MONTH(Performance[[#This Row],[Date]]),Mapping!$K$1:$K$12,Mapping!$L$1:$L$12) -> February | N13: =_xlfn.XLOOKUP(WEEKDAY(Performance[[#This Row],[Date]]),Mapping!$N$1:$N$7,Mapping!$O$1:$O$7,) -> Wednesday
... A81: 4 | B81: =_xlfn.XLOOKUP(Performance[[#This Row],[Session_ID]],Sessions[Session_ID],Sessions[Date],"Not found") -> 46148 | C81: Crunches | D81: 1 | E81: 19 | F81: 7 | G81: 0 | H81: =IF(Performance[[#This Row],[RIR]]="","",10-Performance[[#This Row],[RIR]]) -> 10 | I81: {=_xlfn.XLOOKUP(Performance[[#This Row],[RPE]],RPE_Detalis[[#All],[RPE]],RPE_Detalis[[#All],[Detalis]],"")} -> MAX | J81: =Performance[[#This Row],[Reps]]*Performance[[#This Row],[Weight]] -> 133 | K81: =_xlfn.XLOOKUP(Performance[[#This Row],[Exercise_Name]],Exercises[Exercise_Name],Exercises[Exercise_ID],"Not found") -> EX-007 | L81: =YEAR(Performance[[#This Row],[Date]]) -> 2026 | M81: =_xlfn.XLOOKUP(MONTH(Performance[[#This Row],[Date]]),Mapping!$K$1:$K$12,Mapping!$L$1:$L$12) -> May | N81: =_xlfn.XLOOKUP(WEEKDAY(Performance[[#This Row],[Date]]),Mapping!$N$1:$N$7,Mapping!$O$1:$O$7,) -> Thursday

Sheet Weight
A1: Date | B1: Body weight
A2: 45992 | B2: 80
A3: 45995 | B3: 81
A4: 46011 | B4: 82
A5: 46012 | B5: 83
A6: 46024 | B6: 83.5
A7: 46025 | B7: 84
A8: 46031 | B8: 84
A9: 46040 | B9: 84.3
A10: 46041 | B10: 84.2
A11: 46046 | B11: 83.7
A12: 46053 | B12: 83

Sheet Body_measurements
A1: Date | B1: Neck | C1: Chest | D1: Biceps | E1: Waits | F1: Stomach | G1: Hips | H1: Thigh | I1: Calf
A2: 46003 | B2: 30 | C2: 80 | D2: 31 | E2: 70 | F2: 73 | G2: 70 | H2: 40 | I2: 32
A3: 46011 | B3: 29 | C3: 81 | D3: 31 | E3: 71 | F3: 71 | G3: 71 | H3: 42 | I3: 31

Sheet Mapping
A1: Exercises_Equipment | C1: {=_xlfn.UNIQUE(Sessions!I:I)} -> Year | E1: RPE | F1: Detalis | H1: {=_xlfn.UNIQUE(Performance[[#All],[Exercise_Name]])} -> Exercise_Name | K1: 1 | L1: January | N1: 1 | O1: Monday
A2: Barbell | C2: 2026 | E2: 10 | F2: MAX | H2: Hip bridge from the ground | K2: 2 | L2: February | N2: 2 | O2: Tuesday
A3: Dumbbell | C3: 0 | E3: 9 | F3: Very hard, almost max | H3: Barbell squat | K3: 3 | L3: March | N3: 3 | O3: Wednesday
A4: Machine | E4: 8 | F4: Hard | H4: RDL one leg | K4: 4 | L4: April | N4: 4 | O4: Thursday
A5: Cable | E5: 7 | F5: Hard, but controlled | H5: Calf raises | K5: 5 | L5: May | N5: 5 | O5: Friday
A6: Bodyweight | E6: 6 | F6: Moderately heavy | H6: Abdominal wheel | K6: 6 | L6: June | N6: 6 | O6: Saturday
E7: 5 | F7: Warm-up / technic | H7: Crunches | K7: 7 | L7: July | N7: 7 | O7: Sunday
E8: 4 | F8: Warm-up / technic | K8: 8 | L8: August
E9: 3 | F9: Warm-up / technic | K9: 9 | L9: September
E10: 2 | F10: Warm-up / technic | K10: 10 | L10: October
E11: 1 | F11: Warm-up / technic | K11: 11 | L11: November
E12: 0 | F12: Warm-up / technic | K12: 12 | L12: December
